<!DOCTYPE html>
<html>
<head>
    <title>Trinity Unit Test Report</title>
    <meta http-equiv="Content-Type" content="text/html; charset=UTF-8"/>

<style>
body {
    font-family: Calibri, "Trebuchet MS", sans-serif;
}
* {
    word-break: break-all;
}
table, td, th, .dataid {
    border: 1px solid #aaa;
    border-collapse: collapse;
    background: #fff;
}
section {
    background: rgba(0, 0, 0, 0.05);
    margin: 2ex;
    padding: 1ex;
    border: 1px solid #999;
    border-radius: 5px;
}
h1 {
    font-size: 130%;
}
h2 {
    font-size: 120%;
}
h3 {
    font-size: 100%;
}
h4 {
    font-size: 85%;
}
h1, h2, h3, h4, a[href] {
    cursor: pointer;
    color: #0074d9;
    text-decoration: none;
}
h3 strong, a.failed {
    color: #ff4136;
}
.failed {
    color: #ff4136;
}
a.success {
    color: #3d9970;
}
pre {
    font-family: 'Consolas', 'Deja Vu Sans Mono',
                 'Bitstream Vera Sans Mono', 'Monaco',
                 'Courier New', monospace;
}

.test-details,
.traceback {
    display: none;
}
section:target .test-details {
    display: block;
}

</style>
</head>
<body>
    <h1>Trinity Automated Test Results</h1>
    <h2>2016-11-18 18:02</h2>
    <section>
        <table>
            <tr>
                <th>Class</th>
                <th class="failed">Fail</th>
                <th class="failed">Error</th>
                <th>Skip</th>
                <th>Success</th>
                <th>Total</th>
            </tr>
                <tr>
                    <td>sample_data_tests.TestTrinitySampleData</td>
                    <td class="failed">3</td>
                    <td class="failed">4</td>
                    <td>0</td>
                    <td>0</td>
                    <td>7</td>
                </tr>
                <tr>
                    <td>test_prep.TestTrinityPrepFlag</td>
                    <td>0</td>
                    <td class="failed">18</td>
                    <td>0</td>
                    <td>0</td>
                    <td>18</td>
                </tr>
                <tr>
                    <td>tests.TestTrinity</td>
                    <td class="failed">9</td>
                    <td class="failed">3</td>
                    <td>0</td>
                    <td>9</td>
                    <td>21</td>
                </tr>
            <tr>
                <td><strong>Total</strong></td>
                <td class="failed">12</td>
                <td class="failed">25</td>
                <td>0</td>
                <td>9</td>
                <td>46</td>
            </tr>
        </table>
    </section>
    <h1>Failure details</h1>
            <section>
                <h2>sample_data_tests.TestTrinitySampleData (3 failures, 4 errors)</h2>
                <div>
                        <section id="sample_data_tests.TestTrinitySampleData:test_DE_analysis_EdgeR">
                            <h3>test_DE_analysis_EdgeR: <strong>exceptions.AssertionError</strong></h3>
                            <div class="test-details">
                                <h4>Traceback</h4>
                                <pre class="traceback">Traceback (most recent call last):
  File "/N/soft/rhel6/python/2.7.3/lib/python2.7/unittest/case.py", line 327, in run
    testMethod()
  File "/N/dc2/scratch/befulton/JenkinsTest/src/util/support_scripts/tests/sample_data_tests.py", line 38, in test_DE_analysis_EdgeR
    self.assertTrue(os.path.isfile(check_file), 'DE output file not created')
  File "/N/soft/rhel6/python/2.7.3/lib/python2.7/unittest/case.py", line 420, in assertTrue
    raise self.failureException(msg)
AssertionError: DE output file not created
</pre>
                                <h4>Details</h4>
                                <pre>DE output file not created</pre>
                            </div>
                        </section>
                        <section id="sample_data_tests.TestTrinitySampleData:test_align_and_estimate_abundance">
                            <h3>test_align_and_estimate_abundance: <strong>exceptions.AssertionError</strong></h3>
                            <div class="test-details">
                                <h4>Traceback</h4>
                                <pre class="traceback">Traceback (most recent call last):
  File "/N/soft/rhel6/python/2.7.3/lib/python2.7/unittest/case.py", line 327, in run
    testMethod()
  File "/N/dc2/scratch/befulton/JenkinsTest/src/util/support_scripts/tests/sample_data_tests.py", line 45, in test_align_and_estimate_abundance
    self.assertTrue(os.path.isfile(check_file), 'RSEM-gene.counts.matrix not created')
  File "/N/soft/rhel6/python/2.7.3/lib/python2.7/unittest/case.py", line 420, in assertTrue
    raise self.failureException(msg)
AssertionError: RSEM-gene.counts.matrix not created
</pre>
                                <h4>Details</h4>
                                <pre>RSEM-gene.counts.matrix not created</pre>
                            </div>
                        </section>
                        <section id="sample_data_tests.TestTrinitySampleData:test_full_edgeR_pipeline">
                            <h3>test_full_edgeR_pipeline: <strong>exceptions.AssertionError</strong></h3>
                            <div class="test-details">
                                <h4>Traceback</h4>
                                <pre class="traceback">Traceback (most recent call last):
  File "/N/soft/rhel6/python/2.7.3/lib/python2.7/unittest/case.py", line 327, in run
    testMethod()
  File "/N/dc2/scratch/befulton/JenkinsTest/src/util/support_scripts/tests/sample_data_tests.py", line 49, in test_full_edgeR_pipeline
    self.assertTrue(os.path.isfile(check_file), 'edgeR sorted BAM not created')
  File "/N/soft/rhel6/python/2.7.3/lib/python2.7/unittest/case.py", line 420, in assertTrue
    raise self.failureException(msg)
AssertionError: edgeR sorted BAM not created
</pre>
                                <h4>Details</h4>
                                <pre>edgeR sorted BAM not created</pre>
                            </div>
                        </section>
                        <section id="sample_data_tests.TestTrinitySampleData:test_genome_guided">
                            <h3>test_genome_guided: <strong>exceptions.IOError</strong></h3>
                            <div class="test-details">
                                <h4>Traceback</h4>
                                <pre class="traceback">Traceback (most recent call last):
  File "/N/soft/rhel6/python/2.7.3/lib/python2.7/unittest/case.py", line 327, in run
    testMethod()
  File "/N/dc2/scratch/befulton/JenkinsTest/src/util/support_scripts/tests/sample_data_tests.py", line 13, in test_genome_guided
    'Trinity-GG.fasta')
  File "/N/dc2/scratch/befulton/JenkinsTest/src/util/support_scripts/tests/sample_data_tests.py", line 55, in count_sequences
    handle = open(gg, "rU")
IOError: [Errno 2] No such file or directory: '/N/dc2/scratch/befulton/JenkinsTest/src/sample_data/test_GenomeGuidedTrinity/test_GG_use_bam_trinity_outdir/Trinity-GG.fasta'
</pre>
                                <h4>Details</h4>
                                <pre>[Errno 2] No such file or directory: '/N/dc2/scratch/befulton/JenkinsTest/src/sample_data/test_GenomeGuidedTrinity/test_GG_use_bam_trinity_outdir/Trinity-GG.fasta'</pre>
                            </div>
                        </section>
                        <section id="sample_data_tests.TestTrinitySampleData:test_genome_guided_with_jaccard_clipping">
                            <h3>test_genome_guided_with_jaccard_clipping: <strong>exceptions.IOError</strong></h3>
                            <div class="test-details">
                                <h4>Traceback</h4>
                                <pre class="traceback">Traceback (most recent call last):
  File "/N/soft/rhel6/python/2.7.3/lib/python2.7/unittest/case.py", line 327, in run
    testMethod()
  File "/N/dc2/scratch/befulton/JenkinsTest/src/util/support_scripts/tests/sample_data_tests.py", line 18, in test_genome_guided_with_jaccard_clipping
    'Trinity-GG.fasta')
  File "/N/dc2/scratch/befulton/JenkinsTest/src/util/support_scripts/tests/sample_data_tests.py", line 55, in count_sequences
    handle = open(gg, "rU")
IOError: [Errno 2] No such file or directory: '/N/dc2/scratch/befulton/JenkinsTest/src/sample_data/test_GenomeGuidedTrinity/test_Schizo_trinityGG_jaccard_RF_outdir/Trinity-GG.fasta'
</pre>
                                <h4>Details</h4>
                                <pre>[Errno 2] No such file or directory: '/N/dc2/scratch/befulton/JenkinsTest/src/sample_data/test_GenomeGuidedTrinity/test_Schizo_trinityGG_jaccard_RF_outdir/Trinity-GG.fasta'</pre>
                            </div>
                        </section>
                        <section id="sample_data_tests.TestTrinitySampleData:test_paired_end_normalization">
                            <h3>test_paired_end_normalization: <strong>exceptions.IOError</strong></h3>
                            <div class="test-details">
                                <h4>Traceback</h4>
                                <pre class="traceback">Traceback (most recent call last):
  File "/N/soft/rhel6/python/2.7.3/lib/python2.7/unittest/case.py", line 327, in run
    testMethod()
  File "/N/dc2/scratch/befulton/JenkinsTest/src/util/support_scripts/tests/sample_data_tests.py", line 23, in test_paired_end_normalization
    'reads.left.fq.gz.normalized_K25_C5_pctSD200.fq')
  File "/N/dc2/scratch/befulton/JenkinsTest/src/util/support_scripts/tests/sample_data_tests.py", line 55, in count_sequences
    handle = open(gg, "rU")
IOError: [Errno 2] No such file or directory: '/N/dc2/scratch/befulton/JenkinsTest/src/sample_data/test_InSilicoReadNormalization/reads.left.fq.gz.normalized_K25_C5_pctSD200.fq'
</pre>
                                <h4>Details</h4>
                                <pre>[Errno 2] No such file or directory: '/N/dc2/scratch/befulton/JenkinsTest/src/sample_data/test_InSilicoReadNormalization/reads.left.fq.gz.normalized_K25_C5_pctSD200.fq'</pre>
                            </div>
                        </section>
                        <section id="sample_data_tests.TestTrinitySampleData:test_trinity_assembly">
                            <h3>test_trinity_assembly: <strong>exceptions.IOError</strong></h3>
                            <div class="test-details">
                                <h4>Traceback</h4>
                                <pre class="traceback">Traceback (most recent call last):
  File "/N/soft/rhel6/python/2.7.3/lib/python2.7/unittest/case.py", line 327, in run
    testMethod()
  File "/N/dc2/scratch/befulton/JenkinsTest/src/util/support_scripts/tests/sample_data_tests.py", line 33, in test_trinity_assembly
    seq_count = self.count_sequences('test_Trinity_Assembly', 'trinity_out_dir', 'Trinity.fasta')
  File "/N/dc2/scratch/befulton/JenkinsTest/src/util/support_scripts/tests/sample_data_tests.py", line 55, in count_sequences
    handle = open(gg, "rU")
IOError: [Errno 2] No such file or directory: '/N/dc2/scratch/befulton/JenkinsTest/src/sample_data/test_Trinity_Assembly/trinity_out_dir/Trinity.fasta'
</pre>
                                <h4>Details</h4>
                                <pre>[Errno 2] No such file or directory: '/N/dc2/scratch/befulton/JenkinsTest/src/sample_data/test_Trinity_Assembly/trinity_out_dir/Trinity.fasta'</pre>
                            </div>
                        </section>
                </div>
            </section>
            <section>
                <h2>test_prep.TestTrinityPrepFlag (0 failures, 18 errors)</h2>
                <div>
                        <section id="test_prep.TestTrinityPrepFlag:test_fasta">
                            <h3>test_fasta: <strong>exceptions.IOError</strong></h3>
                            <div class="test-details">
                                <h4>Traceback</h4>
                                <pre class="traceback">Traceback (most recent call last):
  File "/N/soft/rhel6/python/2.7.3/lib/python2.7/unittest/case.py", line 327, in run
    testMethod()
  File "/N/dc2/scratch/befulton/JenkinsTest/src/util/support_scripts/tests/test_prep.py", line 53, in test_fasta
    self.assertEquals(30575, self.count_seqs(), "Unexpected sequence count")
  File "/N/dc2/scratch/befulton/JenkinsTest/src/util/support_scripts/tests/test_prep.py", line 121, in count_seqs
    handle = open("trinity_out_dir/both.fa", "rU")
IOError: [Errno 2] No such file or directory: 'trinity_out_dir/both.fa'
-------------------- >> begin captured stdout << ---------------------
Command line: Trinity --single left1.fa --prep --seqType fa --max_memory 2G --no_version_check --no_normalize_reads

--------------------- >> end captured stdout << ----------------------
</pre>
                                <h4>Details</h4>
                                <pre>[Errno 2] No such file or directory: 'trinity_out_dir/both.fa'
-------------------- >> begin captured stdout << ---------------------
Command line: Trinity --single left1.fa --prep --seqType fa --max_memory 2G --no_version_check --no_normalize_reads

--------------------- >> end captured stdout << ----------------------</pre>
                            </div>
                        </section>
                        <section id="test_prep.TestTrinityPrepFlag:test_fasta_gz">
                            <h3>test_fasta_gz: <strong>exceptions.IOError</strong></h3>
                            <div class="test-details">
                                <h4>Traceback</h4>
                                <pre class="traceback">Traceback (most recent call last):
  File "/N/soft/rhel6/python/2.7.3/lib/python2.7/unittest/case.py", line 327, in run
    testMethod()
  File "/N/dc2/scratch/befulton/JenkinsTest/src/util/support_scripts/tests/test_prep.py", line 57, in test_fasta_gz
    self.assertEquals(30575, self.count_seqs(), "Unexpected sequence count")
  File "/N/dc2/scratch/befulton/JenkinsTest/src/util/support_scripts/tests/test_prep.py", line 121, in count_seqs
    handle = open("trinity_out_dir/both.fa", "rU")
IOError: [Errno 2] No such file or directory: 'trinity_out_dir/both.fa'
-------------------- >> begin captured stdout << ---------------------
Command line: Trinity --single left1.fa.gz --prep --seqType fa --max_memory 2G --no_version_check --no_normalize_reads

--------------------- >> end captured stdout << ----------------------
</pre>
                                <h4>Details</h4>
                                <pre>[Errno 2] No such file or directory: 'trinity_out_dir/both.fa'
-------------------- >> begin captured stdout << ---------------------
Command line: Trinity --single left1.fa.gz --prep --seqType fa --max_memory 2G --no_version_check --no_normalize_reads

--------------------- >> end captured stdout << ----------------------</pre>
                            </div>
                        </section>
                        <section id="test_prep.TestTrinityPrepFlag:test_fasta_gz_paired">
                            <h3>test_fasta_gz_paired: <strong>exceptions.IOError</strong></h3>
                            <div class="test-details">
                                <h4>Traceback</h4>
                                <pre class="traceback">Traceback (most recent call last):
  File "/N/soft/rhel6/python/2.7.3/lib/python2.7/unittest/case.py", line 327, in run
    testMethod()
  File "/N/dc2/scratch/befulton/JenkinsTest/src/util/support_scripts/tests/test_prep.py", line 93, in test_fasta_gz_paired
    self.assertEquals(61150, self.count_seqs(), "Unexpected sequence count")
  File "/N/dc2/scratch/befulton/JenkinsTest/src/util/support_scripts/tests/test_prep.py", line 121, in count_seqs
    handle = open("trinity_out_dir/both.fa", "rU")
IOError: [Errno 2] No such file or directory: 'trinity_out_dir/both.fa'
-------------------- >> begin captured stdout << ---------------------
Command line: Trinity --left left1.fa.gz --right right1.fa.gz --prep --seqType fa --max_memory 2G --no_version_check --no_normalize_reads

--------------------- >> end captured stdout << ----------------------
</pre>
                                <h4>Details</h4>
                                <pre>[Errno 2] No such file or directory: 'trinity_out_dir/both.fa'
-------------------- >> begin captured stdout << ---------------------
Command line: Trinity --left left1.fa.gz --right right1.fa.gz --prep --seqType fa --max_memory 2G --no_version_check --no_normalize_reads

--------------------- >> end captured stdout << ----------------------</pre>
                            </div>
                        </section>
                        <section id="test_prep.TestTrinityPrepFlag:test_fasta_multiple_files_paired">
                            <h3>test_fasta_multiple_files_paired: <strong>exceptions.IOError</strong></h3>
                            <div class="test-details">
                                <h4>Traceback</h4>
                                <pre class="traceback">Traceback (most recent call last):
  File "/N/soft/rhel6/python/2.7.3/lib/python2.7/unittest/case.py", line 327, in run
    testMethod()
  File "/N/dc2/scratch/befulton/JenkinsTest/src/util/support_scripts/tests/test_prep.py", line 101, in test_fasta_multiple_files_paired
    self.assertEquals(122300, self.count_seqs(), "Unexpected sequence count")
  File "/N/dc2/scratch/befulton/JenkinsTest/src/util/support_scripts/tests/test_prep.py", line 121, in count_seqs
    handle = open("trinity_out_dir/both.fa", "rU")
IOError: [Errno 2] No such file or directory: 'trinity_out_dir/both.fa'
-------------------- >> begin captured stdout << ---------------------
Command line: Trinity --left left1.fa,left1.fa.gz --right right1.fa,right1.fa.gz --prep --seqType fa --max_memory 2G --no_version_check --no_normalize_reads --SS_lib_type RF

--------------------- >> end captured stdout << ----------------------
</pre>
                                <h4>Details</h4>
                                <pre>[Errno 2] No such file or directory: 'trinity_out_dir/both.fa'
-------------------- >> begin captured stdout << ---------------------
Command line: Trinity --left left1.fa,left1.fa.gz --right right1.fa,right1.fa.gz --prep --seqType fa --max_memory 2G --no_version_check --no_normalize_reads --SS_lib_type RF

--------------------- >> end captured stdout << ----------------------</pre>
                            </div>
                        </section>
                        <section id="test_prep.TestTrinityPrepFlag:test_fasta_multiple_files_single">
                            <h3>test_fasta_multiple_files_single: <strong>exceptions.IOError</strong></h3>
                            <div class="test-details">
                                <h4>Traceback</h4>
                                <pre class="traceback">Traceback (most recent call last):
  File "/N/soft/rhel6/python/2.7.3/lib/python2.7/unittest/case.py", line 327, in run
    testMethod()
  File "/N/dc2/scratch/befulton/JenkinsTest/src/util/support_scripts/tests/test_prep.py", line 61, in test_fasta_multiple_files_single
    self.assertEquals(61150, self.count_seqs(), "Unexpected sequence count")
  File "/N/dc2/scratch/befulton/JenkinsTest/src/util/support_scripts/tests/test_prep.py", line 121, in count_seqs
    handle = open("trinity_out_dir/both.fa", "rU")
IOError: [Errno 2] No such file or directory: 'trinity_out_dir/both.fa'
-------------------- >> begin captured stdout << ---------------------
Command line: Trinity --single left1.fa,left1.fa.gz --prep --seqType fa --max_memory 2G --no_version_check --no_normalize_reads

--------------------- >> end captured stdout << ----------------------
</pre>
                                <h4>Details</h4>
                                <pre>[Errno 2] No such file or directory: 'trinity_out_dir/both.fa'
-------------------- >> begin captured stdout << ---------------------
Command line: Trinity --single left1.fa,left1.fa.gz --prep --seqType fa --max_memory 2G --no_version_check --no_normalize_reads

--------------------- >> end captured stdout << ----------------------</pre>
                            </div>
                        </section>
                        <section id="test_prep.TestTrinityPrepFlag:test_fasta_multiple_files_single_reverse">
                            <h3>test_fasta_multiple_files_single_reverse: <strong>exceptions.IOError</strong></h3>
                            <div class="test-details">
                                <h4>Traceback</h4>
                                <pre class="traceback">Traceback (most recent call last):
  File "/N/soft/rhel6/python/2.7.3/lib/python2.7/unittest/case.py", line 327, in run
    testMethod()
  File "/N/dc2/scratch/befulton/JenkinsTest/src/util/support_scripts/tests/test_prep.py", line 65, in test_fasta_multiple_files_single_reverse
    self.assertEquals(61150, self.count_seqs(), "Unexpected sequence count")
  File "/N/dc2/scratch/befulton/JenkinsTest/src/util/support_scripts/tests/test_prep.py", line 121, in count_seqs
    handle = open("trinity_out_dir/both.fa", "rU")
IOError: [Errno 2] No such file or directory: 'trinity_out_dir/both.fa'
-------------------- >> begin captured stdout << ---------------------
Command line: Trinity --single left1.fa,left1.fa.gz --prep --seqType fa --max_memory 2G --no_version_check --no_normalize_reads --SS_lib_type R

--------------------- >> end captured stdout << ----------------------
</pre>
                                <h4>Details</h4>
                                <pre>[Errno 2] No such file or directory: 'trinity_out_dir/both.fa'
-------------------- >> begin captured stdout << ---------------------
Command line: Trinity --single left1.fa,left1.fa.gz --prep --seqType fa --max_memory 2G --no_version_check --no_normalize_reads --SS_lib_type R

--------------------- >> end captured stdout << ----------------------</pre>
                            </div>
                        </section>
                        <section id="test_prep.TestTrinityPrepFlag:test_fasta_paired">
                            <h3>test_fasta_paired: <strong>exceptions.IOError</strong></h3>
                            <div class="test-details">
                                <h4>Traceback</h4>
                                <pre class="traceback">Traceback (most recent call last):
  File "/N/soft/rhel6/python/2.7.3/lib/python2.7/unittest/case.py", line 327, in run
    testMethod()
  File "/N/dc2/scratch/befulton/JenkinsTest/src/util/support_scripts/tests/test_prep.py", line 85, in test_fasta_paired
    self.assertEquals(61150, self.count_seqs(), "Unexpected sequence count")
  File "/N/dc2/scratch/befulton/JenkinsTest/src/util/support_scripts/tests/test_prep.py", line 121, in count_seqs
    handle = open("trinity_out_dir/both.fa", "rU")
IOError: [Errno 2] No such file or directory: 'trinity_out_dir/both.fa'
-------------------- >> begin captured stdout << ---------------------
Command line: Trinity --left left1.fa --right right1.fa --prep --seqType fa --max_memory 2G --no_version_check --no_normalize_reads

--------------------- >> end captured stdout << ----------------------
</pre>
                                <h4>Details</h4>
                                <pre>[Errno 2] No such file or directory: 'trinity_out_dir/both.fa'
-------------------- >> begin captured stdout << ---------------------
Command line: Trinity --left left1.fa --right right1.fa --prep --seqType fa --max_memory 2G --no_version_check --no_normalize_reads

--------------------- >> end captured stdout << ----------------------</pre>
                            </div>
                        </section>
                        <section id="test_prep.TestTrinityPrepFlag:test_fastq">
                            <h3>test_fastq: <strong>exceptions.IOError</strong></h3>
                            <div class="test-details">
                                <h4>Traceback</h4>
                                <pre class="traceback">Traceback (most recent call last):
  File "/N/soft/rhel6/python/2.7.3/lib/python2.7/unittest/case.py", line 327, in run
    testMethod()
  File "/N/dc2/scratch/befulton/JenkinsTest/src/util/support_scripts/tests/test_prep.py", line 29, in test_fastq
    self.assertEquals(30575, self.count_seqs(), "Unexpected sequence count")
  File "/N/dc2/scratch/befulton/JenkinsTest/src/util/support_scripts/tests/test_prep.py", line 121, in count_seqs
    handle = open("trinity_out_dir/both.fa", "rU")
IOError: [Errno 2] No such file or directory: 'trinity_out_dir/both.fa'
-------------------- >> begin captured stdout << ---------------------
Command line: Trinity --single left1.fq --prep --seqType fq --max_memory 2G --no_version_check --no_normalize_reads

--------------------- >> end captured stdout << ----------------------
</pre>
                                <h4>Details</h4>
                                <pre>[Errno 2] No such file or directory: 'trinity_out_dir/both.fa'
-------------------- >> begin captured stdout << ---------------------
Command line: Trinity --single left1.fq --prep --seqType fq --max_memory 2G --no_version_check --no_normalize_reads

--------------------- >> end captured stdout << ----------------------</pre>
                            </div>
                        </section>
                        <section id="test_prep.TestTrinityPrepFlag:test_fastq_bz2">
                            <h3>test_fastq_bz2: <strong>exceptions.IOError</strong></h3>
                            <div class="test-details">
                                <h4>Traceback</h4>
                                <pre class="traceback">Traceback (most recent call last):
  File "/N/soft/rhel6/python/2.7.3/lib/python2.7/unittest/case.py", line 327, in run
    testMethod()
  File "/N/dc2/scratch/befulton/JenkinsTest/src/util/support_scripts/tests/test_prep.py", line 37, in test_fastq_bz2
    self.assertEquals(30575, self.count_seqs(), "Unexpected sequence count")
  File "/N/dc2/scratch/befulton/JenkinsTest/src/util/support_scripts/tests/test_prep.py", line 121, in count_seqs
    handle = open("trinity_out_dir/both.fa", "rU")
IOError: [Errno 2] No such file or directory: 'trinity_out_dir/both.fa'
-------------------- >> begin captured stdout << ---------------------
Command line: Trinity --single left1.fq.bz2 --prep --seqType fq --max_memory 2G --no_version_check --no_normalize_reads

--------------------- >> end captured stdout << ----------------------
</pre>
                                <h4>Details</h4>
                                <pre>[Errno 2] No such file or directory: 'trinity_out_dir/both.fa'
-------------------- >> begin captured stdout << ---------------------
Command line: Trinity --single left1.fq.bz2 --prep --seqType fq --max_memory 2G --no_version_check --no_normalize_reads

--------------------- >> end captured stdout << ----------------------</pre>
                            </div>
                        </section>
                        <section id="test_prep.TestTrinityPrepFlag:test_fastq_gz">
                            <h3>test_fastq_gz: <strong>exceptions.IOError</strong></h3>
                            <div class="test-details">
                                <h4>Traceback</h4>
                                <pre class="traceback">Traceback (most recent call last):
  File "/N/soft/rhel6/python/2.7.3/lib/python2.7/unittest/case.py", line 327, in run
    testMethod()
  File "/N/dc2/scratch/befulton/JenkinsTest/src/util/support_scripts/tests/test_prep.py", line 33, in test_fastq_gz
    self.assertEquals(30575, self.count_seqs(), "Unexpected sequence count")
  File "/N/dc2/scratch/befulton/JenkinsTest/src/util/support_scripts/tests/test_prep.py", line 121, in count_seqs
    handle = open("trinity_out_dir/both.fa", "rU")
IOError: [Errno 2] No such file or directory: 'trinity_out_dir/both.fa'
-------------------- >> begin captured stdout << ---------------------
Command line: Trinity --single left1.fq.gz --prep --seqType fq --max_memory 2G --no_version_check --no_normalize_reads

--------------------- >> end captured stdout << ----------------------
</pre>
                                <h4>Details</h4>
                                <pre>[Errno 2] No such file or directory: 'trinity_out_dir/both.fa'
-------------------- >> begin captured stdout << ---------------------
Command line: Trinity --single left1.fq.gz --prep --seqType fq --max_memory 2G --no_version_check --no_normalize_reads

--------------------- >> end captured stdout << ----------------------</pre>
                            </div>
                        </section>
                        <section id="test_prep.TestTrinityPrepFlag:test_fastq_multiple_files_paired">
                            <h3>test_fastq_multiple_files_paired: <strong>exceptions.IOError</strong></h3>
                            <div class="test-details">
                                <h4>Traceback</h4>
                                <pre class="traceback">Traceback (most recent call last):
  File "/N/soft/rhel6/python/2.7.3/lib/python2.7/unittest/case.py", line 327, in run
    testMethod()
  File "/N/dc2/scratch/befulton/JenkinsTest/src/util/support_scripts/tests/test_prep.py", line 77, in test_fastq_multiple_files_paired
    self.assertEquals(122300, self.count_seqs(), "Unexpected sequence count")
  File "/N/dc2/scratch/befulton/JenkinsTest/src/util/support_scripts/tests/test_prep.py", line 121, in count_seqs
    handle = open("trinity_out_dir/both.fa", "rU")
IOError: [Errno 2] No such file or directory: 'trinity_out_dir/both.fa'
-------------------- >> begin captured stdout << ---------------------
Command line: Trinity --left left1.fq,left1.fq.gz --right right1.fq,right1.fq.gz --prep --seqType fq --max_memory 2G --no_version_check --no_normalize_reads

--------------------- >> end captured stdout << ----------------------
</pre>
                                <h4>Details</h4>
                                <pre>[Errno 2] No such file or directory: 'trinity_out_dir/both.fa'
-------------------- >> begin captured stdout << ---------------------
Command line: Trinity --left left1.fq,left1.fq.gz --right right1.fq,right1.fq.gz --prep --seqType fq --max_memory 2G --no_version_check --no_normalize_reads

--------------------- >> end captured stdout << ----------------------</pre>
                            </div>
                        </section>
                        <section id="test_prep.TestTrinityPrepFlag:test_fastq_multiple_files_paired_reverse">
                            <h3>test_fastq_multiple_files_paired_reverse: <strong>exceptions.IOError</strong></h3>
                            <div class="test-details">
                                <h4>Traceback</h4>
                                <pre class="traceback">Traceback (most recent call last):
  File "/N/soft/rhel6/python/2.7.3/lib/python2.7/unittest/case.py", line 327, in run
    testMethod()
  File "/N/dc2/scratch/befulton/JenkinsTest/src/util/support_scripts/tests/test_prep.py", line 81, in test_fastq_multiple_files_paired_reverse
    self.assertEquals(122300, self.count_seqs(), "Unexpected sequence count")
  File "/N/dc2/scratch/befulton/JenkinsTest/src/util/support_scripts/tests/test_prep.py", line 121, in count_seqs
    handle = open("trinity_out_dir/both.fa", "rU")
IOError: [Errno 2] No such file or directory: 'trinity_out_dir/both.fa'
-------------------- >> begin captured stdout << ---------------------
Command line: Trinity --left left1.fq,left1.fq.gz --right right1.fq,right1.fq.gz --prep --seqType fq --max_memory 2G --no_version_check --no_normalize_reads --SS_lib_type RF

--------------------- >> end captured stdout << ----------------------
</pre>
                                <h4>Details</h4>
                                <pre>[Errno 2] No such file or directory: 'trinity_out_dir/both.fa'
-------------------- >> begin captured stdout << ---------------------
Command line: Trinity --left left1.fq,left1.fq.gz --right right1.fq,right1.fq.gz --prep --seqType fq --max_memory 2G --no_version_check --no_normalize_reads --SS_lib_type RF

--------------------- >> end captured stdout << ----------------------</pre>
                            </div>
                        </section>
                        <section id="test_prep.TestTrinityPrepFlag:test_fastq_multiple_files_single">
                            <h3>test_fastq_multiple_files_single: <strong>exceptions.IOError</strong></h3>
                            <div class="test-details">
                                <h4>Traceback</h4>
                                <pre class="traceback">Traceback (most recent call last):
  File "/N/soft/rhel6/python/2.7.3/lib/python2.7/unittest/case.py", line 327, in run
    testMethod()
  File "/N/dc2/scratch/befulton/JenkinsTest/src/util/support_scripts/tests/test_prep.py", line 41, in test_fastq_multiple_files_single
    self.assertEquals(61150, self.count_seqs(), "Unexpected sequence count")
  File "/N/dc2/scratch/befulton/JenkinsTest/src/util/support_scripts/tests/test_prep.py", line 121, in count_seqs
    handle = open("trinity_out_dir/both.fa", "rU")
IOError: [Errno 2] No such file or directory: 'trinity_out_dir/both.fa'
-------------------- >> begin captured stdout << ---------------------
Command line: Trinity --single left1.fq,left1.fq.gz --prep --seqType fq --max_memory 2G --no_version_check --no_normalize_reads

--------------------- >> end captured stdout << ----------------------
</pre>
                                <h4>Details</h4>
                                <pre>[Errno 2] No such file or directory: 'trinity_out_dir/both.fa'
-------------------- >> begin captured stdout << ---------------------
Command line: Trinity --single left1.fq,left1.fq.gz --prep --seqType fq --max_memory 2G --no_version_check --no_normalize_reads

--------------------- >> end captured stdout << ----------------------</pre>
                            </div>
                        </section>
                        <section id="test_prep.TestTrinityPrepFlag:test_fastq_multiple_files_single_bz2">
                            <h3>test_fastq_multiple_files_single_bz2: <strong>exceptions.IOError</strong></h3>
                            <div class="test-details">
                                <h4>Traceback</h4>
                                <pre class="traceback">Traceback (most recent call last):
  File "/N/soft/rhel6/python/2.7.3/lib/python2.7/unittest/case.py", line 327, in run
    testMethod()
  File "/N/dc2/scratch/befulton/JenkinsTest/src/util/support_scripts/tests/test_prep.py", line 45, in test_fastq_multiple_files_single_bz2
    self.assertEquals(61150, self.count_seqs(), "Unexpected sequence count")
  File "/N/dc2/scratch/befulton/JenkinsTest/src/util/support_scripts/tests/test_prep.py", line 121, in count_seqs
    handle = open("trinity_out_dir/both.fa", "rU")
IOError: [Errno 2] No such file or directory: 'trinity_out_dir/both.fa'
-------------------- >> begin captured stdout << ---------------------
Command line: Trinity --single left1.fq.bz2,left1.fq.gz --prep --seqType fq --max_memory 2G --no_version_check --no_normalize_reads

--------------------- >> end captured stdout << ----------------------
</pre>
                                <h4>Details</h4>
                                <pre>[Errno 2] No such file or directory: 'trinity_out_dir/both.fa'
-------------------- >> begin captured stdout << ---------------------
Command line: Trinity --single left1.fq.bz2,left1.fq.gz --prep --seqType fq --max_memory 2G --no_version_check --no_normalize_reads

--------------------- >> end captured stdout << ----------------------</pre>
                            </div>
                        </section>
                        <section id="test_prep.TestTrinityPrepFlag:test_fastq_multiple_files_single_reverse">
                            <h3>test_fastq_multiple_files_single_reverse: <strong>exceptions.IOError</strong></h3>
                            <div class="test-details">
                                <h4>Traceback</h4>
                                <pre class="traceback">Traceback (most recent call last):
  File "/N/soft/rhel6/python/2.7.3/lib/python2.7/unittest/case.py", line 327, in run
    testMethod()
  File "/N/dc2/scratch/befulton/JenkinsTest/src/util/support_scripts/tests/test_prep.py", line 49, in test_fastq_multiple_files_single_reverse
    self.assertEquals(61150, self.count_seqs(), "Unexpected sequence count")
  File "/N/dc2/scratch/befulton/JenkinsTest/src/util/support_scripts/tests/test_prep.py", line 121, in count_seqs
    handle = open("trinity_out_dir/both.fa", "rU")
IOError: [Errno 2] No such file or directory: 'trinity_out_dir/both.fa'
-------------------- >> begin captured stdout << ---------------------
Command line: Trinity --single left1.fq,left1.fq.gz --prep --seqType fq --max_memory 2G --no_version_check --no_normalize_reads --SS_lib_type R

--------------------- >> end captured stdout << ----------------------
</pre>
                                <h4>Details</h4>
                                <pre>[Errno 2] No such file or directory: 'trinity_out_dir/both.fa'
-------------------- >> begin captured stdout << ---------------------
Command line: Trinity --single left1.fq,left1.fq.gz --prep --seqType fq --max_memory 2G --no_version_check --no_normalize_reads --SS_lib_type R

--------------------- >> end captured stdout << ----------------------</pre>
                            </div>
                        </section>
                        <section id="test_prep.TestTrinityPrepFlag:test_paired_fastq">
                            <h3>test_paired_fastq: <strong>exceptions.IOError</strong></h3>
                            <div class="test-details">
                                <h4>Traceback</h4>
                                <pre class="traceback">Traceback (most recent call last):
  File "/N/soft/rhel6/python/2.7.3/lib/python2.7/unittest/case.py", line 327, in run
    testMethod()
  File "/N/dc2/scratch/befulton/JenkinsTest/src/util/support_scripts/tests/test_prep.py", line 69, in test_paired_fastq
    self.assertEquals(61150, self.count_seqs(), "Unexpected sequence count")
  File "/N/dc2/scratch/befulton/JenkinsTest/src/util/support_scripts/tests/test_prep.py", line 121, in count_seqs
    handle = open("trinity_out_dir/both.fa", "rU")
IOError: [Errno 2] No such file or directory: 'trinity_out_dir/both.fa'
-------------------- >> begin captured stdout << ---------------------
Command line: Trinity --left left1.fq --right right1.fq --prep --seqType fq --max_memory 2G --no_version_check --no_normalize_reads

--------------------- >> end captured stdout << ----------------------
</pre>
                                <h4>Details</h4>
                                <pre>[Errno 2] No such file or directory: 'trinity_out_dir/both.fa'
-------------------- >> begin captured stdout << ---------------------
Command line: Trinity --left left1.fq --right right1.fq --prep --seqType fq --max_memory 2G --no_version_check --no_normalize_reads

--------------------- >> end captured stdout << ----------------------</pre>
                            </div>
                        </section>
                        <section id="test_prep.TestTrinityPrepFlag:test_paired_fastq_gz">
                            <h3>test_paired_fastq_gz: <strong>exceptions.IOError</strong></h3>
                            <div class="test-details">
                                <h4>Traceback</h4>
                                <pre class="traceback">Traceback (most recent call last):
  File "/N/soft/rhel6/python/2.7.3/lib/python2.7/unittest/case.py", line 327, in run
    testMethod()
  File "/N/dc2/scratch/befulton/JenkinsTest/src/util/support_scripts/tests/test_prep.py", line 73, in test_paired_fastq_gz
    self.assertEquals(61150, self.count_seqs(), "Unexpected sequence count")
  File "/N/dc2/scratch/befulton/JenkinsTest/src/util/support_scripts/tests/test_prep.py", line 121, in count_seqs
    handle = open("trinity_out_dir/both.fa", "rU")
IOError: [Errno 2] No such file or directory: 'trinity_out_dir/both.fa'
-------------------- >> begin captured stdout << ---------------------
Command line: Trinity --left left1.fq.gz --right right1.fq.gz --prep --seqType fq --max_memory 2G --no_version_check --no_normalize_reads

--------------------- >> end captured stdout << ----------------------
</pre>
                                <h4>Details</h4>
                                <pre>[Errno 2] No such file or directory: 'trinity_out_dir/both.fa'
-------------------- >> begin captured stdout << ---------------------
Command line: Trinity --left left1.fq.gz --right right1.fq.gz --prep --seqType fq --max_memory 2G --no_version_check --no_normalize_reads

--------------------- >> end captured stdout << ----------------------</pre>
                            </div>
                        </section>
                        <section id="test_prep.TestTrinityPrepFlag:test_paired_sequences_have_1_or_2_extension">
                            <h3>test_paired_sequences_have_1_or_2_extension: <strong>exceptions.IOError</strong></h3>
                            <div class="test-details">
                                <h4>Traceback</h4>
                                <pre class="traceback">Traceback (most recent call last):
  File "/N/soft/rhel6/python/2.7.3/lib/python2.7/unittest/case.py", line 327, in run
    testMethod()
  File "/N/dc2/scratch/befulton/JenkinsTest/src/util/support_scripts/tests/test_prep.py", line 89, in test_paired_sequences_have_1_or_2_extension
    self.assertEquals(0, self.count_bad_endings(), "Found sequences with bad endings")
  File "/N/dc2/scratch/befulton/JenkinsTest/src/util/support_scripts/tests/test_prep.py", line 132, in count_bad_endings
    handle = open("trinity_out_dir/both.fa", "rU")
IOError: [Errno 2] No such file or directory: 'trinity_out_dir/both.fa'
-------------------- >> begin captured stdout << ---------------------
Command line: Trinity --left sra_test.fq --right sra_test2.fq --prep --seqType fq --max_memory 2G --no_version_check --no_normalize_reads

--------------------- >> end captured stdout << ----------------------
</pre>
                                <h4>Details</h4>
                                <pre>[Errno 2] No such file or directory: 'trinity_out_dir/both.fa'
-------------------- >> begin captured stdout << ---------------------
Command line: Trinity --left sra_test.fq --right sra_test2.fq --prep --seqType fq --max_memory 2G --no_version_check --no_normalize_reads

--------------------- >> end captured stdout << ----------------------</pre>
                            </div>
                        </section>
                </div>
            </section>
            <section>
                <h2>tests.TestTrinity (9 failures, 3 errors)</h2>
                <div>
                        <section id="tests.TestTrinity:test_Inchworm_handles_compressed_files">
                            <h3>test_Inchworm_handles_compressed_files: <strong>exceptions.AssertionError</strong></h3>
                            <div class="test-details">
                                <h4>Traceback</h4>
                                <pre class="traceback">Traceback (most recent call last):
  File "/N/soft/rhel6/python/2.7.3/lib/python2.7/unittest/case.py", line 327, in run
    testMethod()
  File "/N/dc2/scratch/befulton/JenkinsTest/src/util/support_scripts/tests/tests.py", line 145, in test_Inchworm_handles_compressed_files
    self.assertTrue(2850 <= num_lines <= 3100, msg='Found %s lines' % num_lines)
  File "/N/soft/rhel6/python/2.7.3/lib/python2.7/unittest/case.py", line 420, in assertTrue
    raise self.failureException(msg)
AssertionError: Found 2778 lines
-------------------- >> begin captured stdout << ---------------------
A compressed single file should be handlred correctly by Inchworm
Command line: Trinity --max_memory 2G --seqType fq --single reads.left.fq.gz --SS_lib_type F --no_run_chrysalis

--------------------- >> end captured stdout << ----------------------
</pre>
                                <h4>Details</h4>
                                <pre>Found 2778 lines
-------------------- >> begin captured stdout << ---------------------
A compressed single file should be handlred correctly by Inchworm
Command line: Trinity --max_memory 2G --seqType fq --single reads.left.fq.gz --SS_lib_type F --no_run_chrysalis

--------------------- >> end captured stdout << ----------------------</pre>
                            </div>
                        </section>
                        <section id="tests.TestTrinity:test_QuantifyGraph_works">
                            <h3>test_QuantifyGraph_works: <strong>exceptions.AssertionError</strong></h3>
                            <div class="test-details">
                                <h4>Traceback</h4>
                                <pre class="traceback">Traceback (most recent call last):
  File "/N/soft/rhel6/python/2.7.3/lib/python2.7/unittest/case.py", line 327, in run
    testMethod()
  File "/N/dc2/scratch/befulton/JenkinsTest/src/util/support_scripts/tests/tests.py", line 151, in test_QuantifyGraph_works
    self.assertEquals(0, result, "QuantifyGraph failed")
  File "/N/soft/rhel6/python/2.7.3/lib/python2.7/unittest/case.py", line 511, in assertEqual
    assertion_func(first, second, msg=msg)
  File "/N/soft/rhel6/python/2.7.3/lib/python2.7/unittest/case.py", line 504, in _baseAssertEqual
    raise self.failureException(msg)
AssertionError: QuantifyGraph failed
</pre>
                                <h4>Details</h4>
                                <pre>QuantifyGraph failed</pre>
                            </div>
                        </section>
                        <section id="tests.TestTrinity:test_cleanup_removes_temp_files">
                            <h3>test_cleanup_removes_temp_files: <strong>exceptions.AssertionError</strong></h3>
                            <div class="test-details">
                                <h4>Traceback</h4>
                                <pre class="traceback">Traceback (most recent call last):
  File "/N/soft/rhel6/python/2.7.3/lib/python2.7/unittest/case.py", line 327, in run
    testMethod()
  File "/N/dc2/scratch/befulton/JenkinsTest/src/util/support_scripts/tests/tests.py", line 64, in test_cleanup_removes_temp_files
    msg="Did full_cleanup but output file not created")
  File "/N/soft/rhel6/python/2.7.3/lib/python2.7/unittest/case.py", line 420, in assertTrue
    raise self.failureException(msg)
AssertionError: Did full_cleanup but output file not created
-------------------- >> begin captured stdout << ---------------------
The --full_cleanup flag should ensure that the output directory is gone but the output file remains
Command line: Trinity --seqType fq --max_memory 2G --left reads.left.fq.gz,reads2.left.fq.gz --right reads.right.fq.gz,reads2.right.fq.gz --SS_lib_type RF --CPU 4 --full_cleanup

--------------------- >> end captured stdout << ----------------------
</pre>
                                <h4>Details</h4>
                                <pre>Did full_cleanup but output file not created
-------------------- >> begin captured stdout << ---------------------
The --full_cleanup flag should ensure that the output directory is gone but the output file remains
Command line: Trinity --seqType fq --max_memory 2G --left reads.left.fq.gz,reads2.left.fq.gz --right reads.right.fq.gz,reads2.right.fq.gz --SS_lib_type RF --CPU 4 --full_cleanup

--------------------- >> end captured stdout << ----------------------</pre>
                            </div>
                        </section>
                        <section id="tests.TestTrinity:test_no_JM_specified_error">
                            <h3>test_no_JM_specified_error: <strong>exceptions.AssertionError</strong></h3>
                            <div class="test-details">
                                <h4>Traceback</h4>
                                <pre class="traceback">Traceback (most recent call last):
  File "/N/soft/rhel6/python/2.7.3/lib/python2.7/unittest/case.py", line 327, in run
    testMethod()
  File "/N/dc2/scratch/befulton/JenkinsTest/src/util/support_scripts/tests/tests.py", line 186, in test_no_JM_specified_error
    self.assertTrue("Error, must specify max memory for jellyfish to use, eg.  --max_memory 10G" in error)
  File "/N/soft/rhel6/python/2.7.3/lib/python2.7/unittest/case.py", line 420, in assertTrue
    raise self.failureException(msg)
AssertionError: False is not true
-------------------- >> begin captured stdout << ---------------------
max_memory flag is required

--------------------- >> end captured stdout << ----------------------
</pre>
                                <h4>Details</h4>
                                <pre>False is not true
-------------------- >> begin captured stdout << ---------------------
max_memory flag is required

--------------------- >> end captured stdout << ----------------------</pre>
                            </div>
                        </section>
                        <section id="tests.TestTrinity:test_no_cleanup_leaves_temp_files">
                            <h3>test_no_cleanup_leaves_temp_files: <strong>exceptions.AssertionError</strong></h3>
                            <div class="test-details">
                                <h4>Traceback</h4>
                                <pre class="traceback">Traceback (most recent call last):
  File "/N/soft/rhel6/python/2.7.3/lib/python2.7/unittest/case.py", line 327, in run
    testMethod()
  File "/N/dc2/scratch/befulton/JenkinsTest/src/util/support_scripts/tests/tests.py", line 55, in test_no_cleanup_leaves_temp_files
    self.assertTrue(os.path.exists("trinity_out_dir/%s" % f), msg="%s not found with no_cleanup" % f)
  File "/N/soft/rhel6/python/2.7.3/lib/python2.7/unittest/case.py", line 420, in assertTrue
    raise self.failureException(msg)
AssertionError: both.fa not found with no_cleanup
-------------------- >> begin captured stdout << ---------------------
The --no_cleanup flag should ensure that the output directory is left behind
Command line: Trinity --seqType fq --max_memory 2G --left reads.left.fq.gz,reads2.left.fq.gz --right reads.right.fq.gz,reads2.right.fq.gz --SS_lib_type RF --CPU 4 --no_cleanup

--------------------- >> end captured stdout << ----------------------
</pre>
                                <h4>Details</h4>
                                <pre>both.fa not found with no_cleanup
-------------------- >> begin captured stdout << ---------------------
The --no_cleanup flag should ensure that the output directory is left behind
Command line: Trinity --seqType fq --max_memory 2G --left reads.left.fq.gz,reads2.left.fq.gz --right reads.right.fq.gz,reads2.right.fq.gz --SS_lib_type RF --CPU 4 --no_cleanup

--------------------- >> end captured stdout << ----------------------</pre>
                            </div>
                        </section>
                        <section id="tests.TestTrinity:test_no_distributed_trinity_exec">
                            <h3>test_no_distributed_trinity_exec: <strong>exceptions.AssertionError</strong></h3>
                            <div class="test-details">
                                <h4>Traceback</h4>
                                <pre class="traceback">Traceback (most recent call last):
  File "/N/soft/rhel6/python/2.7.3/lib/python2.7/unittest/case.py", line 327, in run
    testMethod()
  File "/N/dc2/scratch/befulton/JenkinsTest/src/util/support_scripts/tests/tests.py", line 100, in test_no_distributed_trinity_exec
    msg="Inchworm did not appear to run with no_distributed_trinity_exec flag")
  File "/N/soft/rhel6/python/2.7.3/lib/python2.7/unittest/case.py", line 420, in assertTrue
    raise self.failureException(msg)
AssertionError: Inchworm did not appear to run with no_distributed_trinity_exec flag
-------------------- >> begin captured stdout << ---------------------
The --no_distributed_trinity_exec flag should run Jellyfish but not create an output file
Command line: Trinity --max_memory 2G --seqType fq --single reads.left.fq --SS_lib_type F --no_distributed_trinity_exec

--------------------- >> end captured stdout << ----------------------
</pre>
                                <h4>Details</h4>
                                <pre>Inchworm did not appear to run with no_distributed_trinity_exec flag
-------------------- >> begin captured stdout << ---------------------
The --no_distributed_trinity_exec flag should run Jellyfish but not create an output file
Command line: Trinity --max_memory 2G --seqType fq --single reads.left.fq --SS_lib_type F --no_distributed_trinity_exec

--------------------- >> end captured stdout << ----------------------</pre>
                            </div>
                        </section>
                        <section id="tests.TestTrinity:test_output_correctly_changes_dir">
                            <h3>test_output_correctly_changes_dir: <strong>exceptions.AssertionError</strong></h3>
                            <div class="test-details">
                                <h4>Traceback</h4>
                                <pre class="traceback">Traceback (most recent call last):
  File "/N/soft/rhel6/python/2.7.3/lib/python2.7/unittest/case.py", line 327, in run
    testMethod()
  File "/N/dc2/scratch/befulton/JenkinsTest/src/util/support_scripts/tests/tests.py", line 115, in test_output_correctly_changes_dir
    self.assertTrue(os.path.exists("trinity_test"), msg="Changed output directory but it was not created")
  File "/N/soft/rhel6/python/2.7.3/lib/python2.7/unittest/case.py", line 420, in assertTrue
    raise self.failureException(msg)
AssertionError: Changed output directory but it was not created
-------------------- >> begin captured stdout << ---------------------
The --output flag should change the output directory
Command line: Trinity --max_memory 2G --seqType fq --single reads.left.fq --SS_lib_type F --output trinity_test

--------------------- >> end captured stdout << ----------------------
</pre>
                                <h4>Details</h4>
                                <pre>Changed output directory but it was not created
-------------------- >> begin captured stdout << ---------------------
The --output flag should change the output directory
Command line: Trinity --max_memory 2G --seqType fq --single reads.left.fq --SS_lib_type F --output trinity_test

--------------------- >> end captured stdout << ----------------------</pre>
                            </div>
                        </section>
                        <section id="tests.TestTrinity:test_sample_data_seq_count">
                            <h3>test_sample_data_seq_count: <strong>exceptions.IOError</strong></h3>
                            <div class="test-details">
                                <h4>Traceback</h4>
                                <pre class="traceback">Traceback (most recent call last):
  File "/N/soft/rhel6/python/2.7.3/lib/python2.7/unittest/case.py", line 327, in run
    testMethod()
  File "/N/dc2/scratch/befulton/JenkinsTest/src/util/support_scripts/tests/tests.py", line 36, in test_sample_data_seq_count
    handle = open("trinity_out_dir/Trinity.fasta", "rU")
IOError: [Errno 2] No such file or directory: 'trinity_out_dir/Trinity.fasta'
-------------------- >> begin captured stdout << ---------------------
When assembling the sample data, the number of sequences assembled should be between 75 and 100
Command line: Trinity --seqType fq --max_memory 2G --left reads.left.fq.gz,reads2.left.fq.gz --right reads.right.fq.gz,reads2.right.fq.gz --SS_lib_type RF --CPU 4 --no_cleanup

--------------------- >> end captured stdout << ----------------------
</pre>
                                <h4>Details</h4>
                                <pre>[Errno 2] No such file or directory: 'trinity_out_dir/Trinity.fasta'
-------------------- >> begin captured stdout << ---------------------
When assembling the sample data, the number of sequences assembled should be between 75 and 100
Command line: Trinity --seqType fq --max_memory 2G --left reads.left.fq.gz,reads2.left.fq.gz --right reads.right.fq.gz,reads2.right.fq.gz --SS_lib_type RF --CPU 4 --no_cleanup

--------------------- >> end captured stdout << ----------------------</pre>
                            </div>
                        </section>
                        <section id="tests.TestTrinity:test_sample_data_trimmed_and_normalized">
                            <h3>test_sample_data_trimmed_and_normalized: <strong>exceptions.IOError</strong></h3>
                            <div class="test-details">
                                <h4>Traceback</h4>
                                <pre class="traceback">Traceback (most recent call last):
  File "/N/soft/rhel6/python/2.7.3/lib/python2.7/unittest/case.py", line 327, in run
    testMethod()
  File "/N/dc2/scratch/befulton/JenkinsTest/src/util/support_scripts/tests/tests.py", line 45, in test_sample_data_trimmed_and_normalized
    handle = open("trinity_out_dir/Trinity.fasta", "rU")
IOError: [Errno 2] No such file or directory: 'trinity_out_dir/Trinity.fasta'
-------------------- >> begin captured stdout << ---------------------
When assembling the sample data with the --trimmomatic --normalize_reads flags, the number of sequences assembled should be between 75 and 85
Command line: Trinity --seqType fq --max_memory 2G --left reads.left.fq.gz,reads2.left.fq.gz --right reads.right.fq.gz,reads2.right.fq.gz --SS_lib_type RF --CPU 4 --trimmomatic --normalize_reads --no_cleanup

--------------------- >> end captured stdout << ----------------------
</pre>
                                <h4>Details</h4>
                                <pre>[Errno 2] No such file or directory: 'trinity_out_dir/Trinity.fasta'
-------------------- >> begin captured stdout << ---------------------
When assembling the sample data with the --trimmomatic --normalize_reads flags, the number of sequences assembled should be between 75 and 85
Command line: Trinity --seqType fq --max_memory 2G --left reads.left.fq.gz,reads2.left.fq.gz --right reads.right.fq.gz,reads2.right.fq.gz --SS_lib_type RF --CPU 4 --trimmomatic --normalize_reads --no_cleanup

--------------------- >> end captured stdout << ----------------------</pre>
                            </div>
                        </section>
                        <section id="tests.TestTrinity:test_scaffold_iworm_contigs">
                            <h3>test_scaffold_iworm_contigs: <strong>exceptions.OSError</strong></h3>
                            <div class="test-details">
                                <h4>Traceback</h4>
                                <pre class="traceback">Traceback (most recent call last):
  File "/N/soft/rhel6/python/2.7.3/lib/python2.7/unittest/case.py", line 327, in run
    testMethod()
  File "/N/dc2/scratch/befulton/JenkinsTest/src/util/support_scripts/tests/tests.py", line 124, in test_scaffold_iworm_contigs
    f = subprocess.check_output([exe, bamfile, ifile]).split('\n')
  File "/N/soft/rhel6/python/2.7.3/lib/python2.7/subprocess.py", line 537, in check_output
    process = Popen(stdout=PIPE, *popenargs, **kwargs)
  File "/N/soft/rhel6/python/2.7.3/lib/python2.7/subprocess.py", line 679, in __init__
    errread, errwrite)
  File "/N/soft/rhel6/python/2.7.3/lib/python2.7/subprocess.py", line 1249, in _execute_child
    raise child_exception
OSError: [Errno 2] No such file or directory
-------------------- >> begin captured stdout << ---------------------
scaffold_iworm_contigs works as expected

--------------------- >> end captured stdout << ----------------------
</pre>
                                <h4>Details</h4>
                                <pre>[Errno 2] No such file or directory
-------------------- >> begin captured stdout << ---------------------
scaffold_iworm_contigs works as expected

--------------------- >> end captured stdout << ----------------------</pre>
                            </div>
                        </section>
                        <section id="tests.TestTrinity:test_set_no_cleanup_and_full_cleanup_error">
                            <h3>test_set_no_cleanup_and_full_cleanup_error: <strong>exceptions.AssertionError</strong></h3>
                            <div class="test-details">
                                <h4>Traceback</h4>
                                <pre class="traceback">Traceback (most recent call last):
  File "/N/soft/rhel6/python/2.7.3/lib/python2.7/unittest/case.py", line 327, in run
    testMethod()
  File "/N/dc2/scratch/befulton/JenkinsTest/src/util/support_scripts/tests/tests.py", line 196, in test_set_no_cleanup_and_full_cleanup_error
    self.assertTrue("cannot set --no_cleanup and --full_cleanup as they contradict" in error)
  File "/N/soft/rhel6/python/2.7.3/lib/python2.7/unittest/case.py", line 420, in assertTrue
    raise self.failureException(msg)
AssertionError: False is not true
-------------------- >> begin captured stdout << ---------------------
Setting no_cleanup and full_cleanup together results in an error

--------------------- >> end captured stdout << ----------------------
</pre>
                                <h4>Details</h4>
                                <pre>False is not true
-------------------- >> begin captured stdout << ---------------------
Setting no_cleanup and full_cleanup together results in an error

--------------------- >> end captured stdout << ----------------------</pre>
                            </div>
                        </section>
                        <section id="tests.TestTrinity:test_version">
                            <h3>test_version: <strong>exceptions.AssertionError</strong></h3>
                            <div class="test-details">
                                <h4>Traceback</h4>
                                <pre class="traceback">Traceback (most recent call last):
  File "/N/soft/rhel6/python/2.7.3/lib/python2.7/unittest/case.py", line 327, in run
    testMethod()
  File "/N/dc2/scratch/befulton/JenkinsTest/src/util/support_scripts/tests/tests.py", line 167, in test_version
    self.assertTrue('Trinity version: __TRINITY_VERSION_TAG__' in e.output)
  File "/N/soft/rhel6/python/2.7.3/lib/python2.7/unittest/case.py", line 420, in assertTrue
    raise self.failureException(msg)
AssertionError: False is not true
-------------------- >> begin captured stdout << ---------------------
Version flag should return version information

--------------------- >> end captured stdout << ----------------------
</pre>
                                <h4>Details</h4>
                                <pre>False is not true
-------------------- >> begin captured stdout << ---------------------
Version flag should return version information

--------------------- >> end captured stdout << ----------------------</pre>
                            </div>
                        </section>
                </div>
            </section>

    <h1>All tests</h1>
    <section>
        <h2>sample_data_tests.TestTrinitySampleData (3 failures, 4 errors)</h2>
        <ul>
                <li><a class="failed" href="#sample_data_tests.TestTrinitySampleData:test_DE_analysis_EdgeR">test_DE_analysis_EdgeR</a></li>
                <li><a class="failed" href="#sample_data_tests.TestTrinitySampleData:test_align_and_estimate_abundance">test_align_and_estimate_abundance</a></li>
                <li><a class="failed" href="#sample_data_tests.TestTrinitySampleData:test_full_edgeR_pipeline">test_full_edgeR_pipeline</a></li>
                <li><a class="failed" href="#sample_data_tests.TestTrinitySampleData:test_genome_guided">test_genome_guided</a></li>
                <li><a class="failed" href="#sample_data_tests.TestTrinitySampleData:test_genome_guided_with_jaccard_clipping">test_genome_guided_with_jaccard_clipping</a></li>
                <li><a class="failed" href="#sample_data_tests.TestTrinitySampleData:test_paired_end_normalization">test_paired_end_normalization</a></li>
                <li><a class="failed" href="#sample_data_tests.TestTrinitySampleData:test_trinity_assembly">test_trinity_assembly</a></li>
        </ul>
    </section>
    <section>
        <h2>test_prep.TestTrinityPrepFlag (0 failures, 18 errors)</h2>
        <ul>
                <li><a class="failed" href="#test_prep.TestTrinityPrepFlag:test_fasta">test_fasta</a></li>
                <li><a class="failed" href="#test_prep.TestTrinityPrepFlag:test_fasta_gz">test_fasta_gz</a></li>
                <li><a class="failed" href="#test_prep.TestTrinityPrepFlag:test_fasta_gz_paired">test_fasta_gz_paired</a></li>
                <li><a class="failed" href="#test_prep.TestTrinityPrepFlag:test_fasta_multiple_files_paired">test_fasta_multiple_files_paired</a></li>
                <li><a class="failed" href="#test_prep.TestTrinityPrepFlag:test_fasta_multiple_files_single">test_fasta_multiple_files_single</a></li>
                <li><a class="failed" href="#test_prep.TestTrinityPrepFlag:test_fasta_multiple_files_single_reverse">test_fasta_multiple_files_single_reverse</a></li>
                <li><a class="failed" href="#test_prep.TestTrinityPrepFlag:test_fasta_paired">test_fasta_paired</a></li>
                <li><a class="failed" href="#test_prep.TestTrinityPrepFlag:test_fastq">test_fastq</a></li>
                <li><a class="failed" href="#test_prep.TestTrinityPrepFlag:test_fastq_bz2">test_fastq_bz2</a></li>
                <li><a class="failed" href="#test_prep.TestTrinityPrepFlag:test_fastq_gz">test_fastq_gz</a></li>
                <li><a class="failed" href="#test_prep.TestTrinityPrepFlag:test_fastq_multiple_files_paired">test_fastq_multiple_files_paired</a></li>
                <li><a class="failed" href="#test_prep.TestTrinityPrepFlag:test_fastq_multiple_files_paired_reverse">test_fastq_multiple_files_paired_reverse</a></li>
                <li><a class="failed" href="#test_prep.TestTrinityPrepFlag:test_fastq_multiple_files_single">test_fastq_multiple_files_single</a></li>
                <li><a class="failed" href="#test_prep.TestTrinityPrepFlag:test_fastq_multiple_files_single_bz2">test_fastq_multiple_files_single_bz2</a></li>
                <li><a class="failed" href="#test_prep.TestTrinityPrepFlag:test_fastq_multiple_files_single_reverse">test_fastq_multiple_files_single_reverse</a></li>
                <li><a class="failed" href="#test_prep.TestTrinityPrepFlag:test_paired_fastq">test_paired_fastq</a></li>
                <li><a class="failed" href="#test_prep.TestTrinityPrepFlag:test_paired_fastq_gz">test_paired_fastq_gz</a></li>
                <li><a class="failed" href="#test_prep.TestTrinityPrepFlag:test_paired_sequences_have_1_or_2_extension">test_paired_sequences_have_1_or_2_extension</a></li>
        </ul>
    </section>
    <section>
        <h2>tests.TestTrinity (9 failures, 3 errors)</h2>
        <ul>
                <li><a class="failed" href="#tests.TestTrinity:test_Inchworm_handles_compressed_files">test_Inchworm_handles_compressed_files</a></li>
                <li><a class="failed" href="#tests.TestTrinity:test_QuantifyGraph_works">test_QuantifyGraph_works</a></li>
                <li><a class="success">test_cite</a></li>
                <li><a class="failed" href="#tests.TestTrinity:test_cleanup_removes_temp_files">test_cleanup_removes_temp_files</a></li>
                <li><a class="success">test_invalid_option_error</a></li>
                <li><a class="failed" href="#tests.TestTrinity:test_no_JM_specified_error">test_no_JM_specified_error</a></li>
                <li><a class="success">test_no_bowtie</a></li>
                <li><a class="failed" href="#tests.TestTrinity:test_no_cleanup_leaves_temp_files">test_no_cleanup_leaves_temp_files</a></li>
                <li><a class="failed" href="#tests.TestTrinity:test_no_distributed_trinity_exec">test_no_distributed_trinity_exec</a></li>
                <li><a class="success">test_no_run_chrysalis</a></li>
                <li><a class="success">test_no_run_inchworm</a></li>
                <li><a class="failed" href="#tests.TestTrinity:test_output_correctly_changes_dir">test_output_correctly_changes_dir</a></li>
                <li><a class="failed" href="#tests.TestTrinity:test_sample_data_seq_count">test_sample_data_seq_count</a></li>
                <li><a class="failed" href="#tests.TestTrinity:test_sample_data_trimmed_and_normalized">test_sample_data_trimmed_and_normalized</a></li>
                <li><a class="failed" href="#tests.TestTrinity:test_scaffold_iworm_contigs">test_scaffold_iworm_contigs</a></li>
                <li><a class="failed" href="#tests.TestTrinity:test_set_no_cleanup_and_full_cleanup_error">test_set_no_cleanup_and_full_cleanup_error</a></li>
                <li><a class="success">test_show_full_usage_info</a></li>
                <li><a class="success">test_single_end_with_fa_and_reverse</a></li>
                <li><a class="success">test_single_end_with_fq</a></li>
                <li><a class="success">test_single_end_with_rf_lib_type_error</a></li>
                <li><a class="failed" href="#tests.TestTrinity:test_version">test_version</a></li>
        </ul>
    </section>
</body>
<script>
    Array.prototype.forEach.call(document.querySelectorAll('h1, h2, h3, h4'), function(el) {
        el.addEventListener('click', function() {
            el.nextElementSibling.style.display = document.defaultView.getComputedStyle(el.nextElementSibling).display == 'none' ? 'block' : 'none';
        })
    })
</script>
</html>